from pyzeebe.errors.pyzeebe_errors import PyZeebeError


class InvalidOAuthCredentialsError(PyZeebeError):
    def __init__(self, url: str, client_id: str, audience: str) -> None:
        super().__init__(
            f"Invalid OAuth credentials supplied for {url} with audience {audience} and client id {client_id}"
        )


class InvalidCamundaCloudCredentialsError(PyZeebeError):
    def __init__(self, client_id: str, cluster_id: str) -> None:
        super().__init__(f"Invalid credentials supplied for cluster {cluster_id} with client {client_id}")
